<?xml version="1.0"?>
<robot xmlns:xacro="http://www.ros.org/wiki/xacro" >
    <xacro:macro name="servo_mount" params="name h w d ">
        <link name="${name}">
            <visual>
                <origin xyz="0 0.015 -0.02" rpy="0 0 0"/>
                <geometry>
                    <box size="${h} ${w} ${d}" />
                </geometry>
                <material name="grey">
                    <color rgba="0.2 0.2 0.2 1.0"/>
                </material>
            </visual>
            <collision>
                <origin xyz="0 0.015 -0.02" rpy="0 0 0"/>
                <geometry>
                    <box size="${h} ${w} ${d}" />
                </geometry>
            </collision>
        </link>
    </xacro:macro>

    <xacro:macro name="servo_joint" params="name parent child flip">
        <joint name="${name}" type="revolute">
            <origin xyz="0.0 0.01 0.0001" rpy="0 0 0"/>
            <parent link="${parent}"/>
            <child link="${child}"/>
            <axis xyz="0 0 ${flip}"/>
            <limit lower="${-135/180*pi}" upper="${135/180*pi}" velocity="100" effort="100"/>
        </joint>
    </xacro:macro>
</robot>
